Workbook

Sheet Checklist
A1: Edu-Dubai Training & Consulting
A2: CARF 2026-27 OPERATIONAL READINESS CHECKLIST
A3: Action Items Across All 6 CARF Risk Zones · Edu-Dubai - Training | Legal |Consulting
A4: DATA COLLECTION LIVE: January 1, 2026 · FIRST REPORTS DUE: May 31, 2027 · JURISDICTIONS COMMITTED: 75+ worldwide
A5: HOW TO USE · Mark X in the Yes, No, or In Progress column that reflects your institution's current status for each action item. One mark per row. Dashboard on the next tab updates automatically.
F6: STATUS — Mark X in one column
A7: # | B7: Risk Zone | C7: Action Item | D7: Guidance / Note | E7: Priority | F7: Yes | G7: No | H7: In Progress | I7: Owner | J7: Target Date | K7: Notes
A8: RISK 01 — Self-Certification & Due Diligence Failures
A9: 1 | B9: Self-Certification & Due Diligence Failures | C9: Map every onboarding flow that touches a crypto-asset user. | D9: New accounts opened from Jan 1, 2026 must capture a valid self-certification at the point of onboarding. | E9: Critical
A10: 2 | B10: Self-Certification & Due Diligence Failures | C10: Identify all pre-existing accounts missing a valid self-certification. | D10: Run a full client-base sweep — historical KYC records were not designed with CARF fields in mind. | E10: Critical
A11: 3 | B11: Self-Certification & Due Diligence Failures | C11: Build or confirm a remediation workflow with reminder cadence. | D11: DAC8 requires two reminders within a 60-day window before a mandatory account freeze applies. | E11: Critical
A12: 4 | B12: Self-Certification & Due Diligence Failures | C12: Implement TIN format validation across every jurisdiction you operate in. | D12: Validate structure and checksum, not just presence of a value. | E12: High
A13: 5 | B13: Self-Certification & Due Diligence Failures | C13: Cross-check self-certifications against existing KYC/AML data for conflicting indicia. | D13: A documented 'reason to know' review process protects against strict liability for simple failures. | E13: High
A14: 6 | B14: Self-Certification & Due Diligence Failures | C14: Confirm your account-freeze mechanism actually blocks reportable transactions, not just new sign-ups. | D14: DAC8's freeze obligation applies to existing reportable activity, not only onboarding. | E14: High
A15: RISK 02 — Transaction Data Overload & Accuracy
A16: 7 | B16: Transaction Data Overload & Accuracy | C16: Document a single, defensible FMV methodology and apply it consistently. | D16: Choose your reference price source (own order book, third-party aggregator, designated exchange) and write it down. | E16: Critical
A17: 8 | B17: Transaction Data Overload & Accuracy | C17: Build FMV calculation logic for every crypto-to-crypto swap, not just crypto-to-fiat trades. | D17: Both legs of a swap must be valued independently and reconciled. | E17: Critical
A18: 9 | B18: Transaction Data Overload & Accuracy | C18: Confirm your system can reconcile on-chain transaction data with off-chain customer records. | D18: Every blockchain hash must correctly link back to a real customer identity and a fiat valuation. | E18: High
A19: 10 | B19: Transaction Data Overload & Accuracy | C19: Classify NFTs, stablecoins, and tokenized assets correctly per jurisdiction. | D19: Confirm de minimis thresholds for NFTs and check whether any stablecoin qualifies as a Specified Electronic Money Product under CRS 2.0. | E19: High
A20: 11 | B20: Transaction Data Overload & Accuracy | C20: Test your CARF XML schema output against the OECD's latest published schema version. | D20: Confirm jurisdiction-specific schema variants (UK, EU/DAC8, Singapore transitional codes) are correctly generated. | E20: High
A21: 12 | B21: Transaction Data Overload & Accuracy | C21: Stress-test your data pipeline against realistic transaction volumes. | D21: Crypto markets trade 24/7 — confirm your system does not degrade under continuous, high-frequency reporting loads. | E21: Medium
A22: RISK 03 — Governance Silos — CARF / CRS / FATCA Overlap
A23: 13 | B23: Governance Silos — CARF / CRS / FATCA Overlap | C23: Determine whether your institution is simultaneously an RFI under CRS and an RCASP under CARF. | D23: Dual status is common and must be explicitly mapped, not assumed away. | E23: Critical
A24: 14 | B24: Governance Silos — CARF / CRS / FATCA Overlap | C24: Apply the OECD's overlap mitigation rules to prevent double-reporting the same client. | D24: A client holding both traditional and digital assets should not be reported twice with contradictory data. | E24: Critical
A25: 15 | B25: Governance Silos — CARF / CRS / FATCA Overlap | C25: Assign a single, named owner for CARF compliance across tax, compliance, ops, and IT. | D25: Governance gaps surface late and usually under deadline pressure — fix ownership before that happens. | E25: High
A26: 16 | B26: Governance Silos — CARF / CRS / FATCA Overlap | C26: Reconcile entity and user classification logic between your CRS and CARF systems. | D26: The same client should not be classified differently depending on which framework is applied. | E26: Medium
A27: RISK 04 — Timeline Pressure & Scalability Failures
A28: 17 | B28: Timeline Pressure & Scalability Failures | C28: Confirm GDPR (or equivalent local privacy law) notification language is reconciled with CARF reporting obligations. | D28: Customers must be informed of reporting without implying it is optional or consent-based. | E28: Critical
A29: 18 | B29: Timeline Pressure & Scalability Failures | C29: Confirm a documented legal basis exists for retaining CARF data despite any erasure requests. | D29: A CARF reporting obligation generally overrides a GDPR right-to-erasure request — document why. | E29: High
A30: 19 | B30: Timeline Pressure & Scalability Failures | C30: Integrate AML/KYC data fields with CARF-required fields (TIN, tax residency) in one data model. | D30: Avoid maintaining two disconnected pools of customer data that must be reconciled by hand. | E30: High
A31: 20 | B31: Timeline Pressure & Scalability Failures | C31: Move from periodic batch monitoring to continuous, event-driven data processing. | D31: Self-certification deadlines and freeze triggers require real-time tracking, not quarterly review cycles. | E31: Medium
A32: 21 | B32: Timeline Pressure & Scalability Failures | C32: Confirm registration deadlines for every jurisdiction you operate in are tracked on a master compliance calendar. | D32: E.g. UK RCASPs must register with HMRC by January 1, 2027 — separate from the reporting deadline. | E32: High
A33: RISK 05 — Penalty, License & Reputational Exposure
A34: 22 | B34: Penalty, License & Reputational Exposure | C34: Map your specific penalty exposure across every jurisdiction you operate in. | D34: DAC8: €20K–€500K per violation. UK: £100–£300 per customer, plus daily defaults. UAE: AED 20K–250K. | E34: Critical
A35: 23 | B35: Penalty, License & Reputational Exposure | C35: Confirm an independent, third-party-reviewable audit trail exists for every classification and remediation decision. | D35: Documented evidence of consistent process is your strongest protection during an audit. | E35: Critical
A36: 24 | B36: Penalty, License & Reputational Exposure | C36: Brief senior leadership and directors on personal liability exposure under severe non-compliance scenarios. | D36: Several regimes escalate beyond institutional fines to individual director liability. | E36: High
A37: 25 | B37: Penalty, License & Reputational Exposure | C37: Confirm license-holding entities understand revocation risk under DAC8 and equivalent regimes. | D37: Market exclusion is a realistic consequence, not a theoretical one, for sustained non-compliance. | E37: Medium
A38: RISK 06 — Missed Change of Circumstances
A39: 26 | B39: Missed Change of Circumstances | C39: Replace annual clean-up cycles with continuous changes-in-circumstances monitoring. | D39: CARF treats a delayed correction as a compliance breach for the period the wrong information was on file. | E39: Critical
A40: 27 | B40: Missed Change of Circumstances | C40: Build automated detection for the five key change triggers. | D40: Tax residency change, new jurisdiction account, nationality change, controlling person update, account classification shift. | E40: Critical
...

Sheet Dashboard
A1: Edu-Dubai Training & Consulting
A2: EDU-DUBAI CARF 2026-27 READINESS DASHBOARD
A3: Progress across all 6 CARF Risk Zones — auto-updated from Checklist tab
A5: OVERALL READINESS SUMMARY
B6: Total Items | C6: Completed (Yes) | D6: Not Started (No) | E6: In Progress | F6: % Complete | G6: Outstanding
B7: 29 | C7: =COUNTIF(Checklist!F:F,"X") -> 0 | D7: =COUNTIF(Checklist!G:G,"X") -> 0 | E7: =COUNTIF(Checklist!H:H,"X") -> 0 | F7: =IFERROR(C7/29,0) -> 0 | G7: =29-C7 -> 29
A9: PROGRESS BY RISK ZONE
A10: # | B10: Risk Zone | C10: Total Items | D10: Completed (Yes) | E10: Not Started (No) | F10: In Progress | G10: % Complete
A11: 01 | B11: Self-Certification & Due Diligence Failures | C11: 6 | D11: =SUMPRODUCT(((Checklist!F9="X")+(Checklist!F10="X")+(Checklist!F11="X")+(Checklist!F12="X")+(Checklist!F13="X")+(Checklist!F14="X"))*1) -> 0 | E11: =SUMPRODUCT(((Checklist!G9="X")+(Checklist!G10="X")+(Checklist!G11="X")+(Checklist!G12="X")+(Checklist!G13="X")+(Checklist!G14="X"))*1) -> 0 | F11: =SUMPRODUCT(((Checklist!H9="X")+(Checklist!H10="X")+(Checklist!H11="X")+(Checklist!H12="X")+(Checklist!H13="X")+(Checklist!H14="X"))*1) -> 0 | G11: =IFERROR(D11/6,0) -> 0
A12: 02 | B12: Transaction Data Overload & Accuracy | C12: 6 | D12: =SUMPRODUCT(((Checklist!F16="X")+(Checklist!F17="X")+(Checklist!F18="X")+(Checklist!F19="X")+(Checklist!F20="X")+(Checklist!F21="X"))*1) -> 0 | E12: =SUMPRODUCT(((Checklist!G16="X")+(Checklist!G17="X")+(Checklist!G18="X")+(Checklist!G19="X")+(Checklist!G20="X")+(Checklist!G21="X"))*1) -> 0 | F12: =SUMPRODUCT(((Checklist!H16="X")+(Checklist!H17="X")+(Checklist!H18="X")+(Checklist!H19="X")+(Checklist!H20="X")+(Checklist!H21="X"))*1) -> 0 | G12: =IFERROR(D12/6,0) -> 0
A13: 03 | B13: Governance Silos — CARF / CRS / FATCA Overlap | C13: 4 | D13: =SUMPRODUCT(((Checklist!F23="X")+(Checklist!F24="X")+(Checklist!F25="X")+(Checklist!F26="X"))*1) -> 0 | E13: =SUMPRODUCT(((Checklist!G23="X")+(Checklist!G24="X")+(Checklist!G25="X")+(Checklist!G26="X"))*1) -> 0 | F13: =SUMPRODUCT(((Checklist!H23="X")+(Checklist!H24="X")+(Checklist!H25="X")+(Checklist!H26="X"))*1) -> 0 | G13: =IFERROR(D13/4,0) -> 0
A14: 04 | B14: Timeline Pressure & Scalability Failures | C14: 5 | D14: =SUMPRODUCT(((Checklist!F28="X")+(Checklist!F29="X")+(Checklist!F30="X")+(Checklist!F31="X")+(Checklist!F32="X"))*1) -> 0 | E14: =SUMPRODUCT(((Checklist!G28="X")+(Checklist!G29="X")+(Checklist!G30="X")+(Checklist!G31="X")+(Checklist!G32="X"))*1) -> 0 | F14: =SUMPRODUCT(((Checklist!H28="X")+(Checklist!H29="X")+(Checklist!H30="X")+(Checklist!H31="X")+(Checklist!H32="X"))*1) -> 0 | G14: =IFERROR(D14/5,0) -> 0
A15: 05 | B15: Penalty, License & Reputational Exposure | C15: 4 | D15: =SUMPRODUCT(((Checklist!F34="X")+(Checklist!F35="X")+(Checklist!F36="X")+(Checklist!F37="X"))*1) -> 0 | E15: =SUMPRODUCT(((Checklist!G34="X")+(Checklist!G35="X")+(Checklist!G36="X")+(Checklist!G37="X"))*1) -> 0 | F15: =SUMPRODUCT(((Checklist!H34="X")+(Checklist!H35="X")+(Checklist!H36="X")+(Checklist!H37="X"))*1) -> 0 | G15: =IFERROR(D15/4,0) -> 0
A16: 06 | B16: Missed Change of Circumstances | C16: 4 | D16: =SUMPRODUCT(((Checklist!F39="X")+(Checklist!F40="X")+(Checklist!F41="X")+(Checklist!F42="X"))*1) -> 0 | E16: =SUMPRODUCT(((Checklist!G39="X")+(Checklist!G40="X")+(Checklist!G41="X")+(Checklist!G42="X"))*1) -> 0 | F16: =SUMPRODUCT(((Checklist!H39="X")+(Checklist!H40="X")+(Checklist!H41="X")+(Checklist!H42="X"))*1) -> 0 | G16: =IFERROR(D16/4,0) -> 0
A18: COMPLETION BY PRIORITY
A19: Priority | B19: Total | C19: Yes | D19: No | E19: In Progress | F19: % Complete
A20: Critical | B20: 12 | C20: =SUMPRODUCT(((Checklist!F9="X")+(Checklist!F10="X")+(Checklist!F11="X")+(Checklist!F16="X")+(Checklist!F17="X")+(Checklist!F23="X")+(Checklist!F24="X")+(Checklist!F28="X")+(Checklist!F34="X")+(Checklist!F35="X")+(Checklist!F39="X")+(Checklist!F40="X"))*1) -> 0 | D20: =SUMPRODUCT(((Checklist!G9="X")+(Checklist!G10="X")+(Checklist!G11="X")+(Checklist!G16="X")+(Checklist!G17="X")+(Checklist!G23="X")+(Checklist!G24="X")+(Checklist!G28="X")+(Checklist!G34="X")+(Checklist!G35="X")+(Checklist!G39="X")+(Checklist!G40="X"))*1) -> 0 | E20: =SUMPRODUCT(((Checklist!H9="X")+(Checklist!H10="X")+(Checklist!H11="X")+(Checklist!H16="X")+(Checklist!H17="X")+(Checklist!H23="X")+(Checklist!H24="X")+(Checklist!H28="X")+(Checklist!H34="X")+(Checklist!H35="X")+(Checklist!H39="X")+(Checklist!H40="X"))*1) -> 0 | F20: =IFERROR(C20/12,0) -> 0
A21: High | B21: 12 | C21: =SUMPRODUCT(((Checklist!F12="X")+(Checklist!F13="X")+(Checklist!F14="X")+(Checklist!F18="X")+(Checklist!F19="X")+(Checklist!F20="X")+(Checklist!F25="X")+(Checklist!F29="X")+(Checklist!F30="X")+(Checklist!F32="X")+(Checklist!F36="X")+(Checklist!F41="X"))*1) -> 0 | D21: =SUMPRODUCT(((Checklist!G12="X")+(Checklist!G13="X")+(Checklist!G14="X")+(Checklist!G18="X")+(Checklist!G19="X")+(Checklist!G20="X")+(Checklist!G25="X")+(Checklist!G29="X")+(Checklist!G30="X")+(Checklist!G32="X")+(Checklist!G36="X")+(Checklist!G41="X"))*1) -> 0 | E21: =SUMPRODUCT(((Checklist!H12="X")+(Checklist!H13="X")+(Checklist!H14="X")+(Checklist!H18="X")+(Checklist!H19="X")+(Checklist!H20="X")+(Checklist!H25="X")+(Checklist!H29="X")+(Checklist!H30="X")+(Checklist!H32="X")+(Checklist!H36="X")+(Checklist!H41="X"))*1) -> 0 | F21: =IFERROR(C21/12,0) -> 0
A22: Medium | B22: 5 | C22: =SUMPRODUCT(((Checklist!F21="X")+(Checklist!F26="X")+(Checklist!F31="X")+(Checklist!F37="X")+(Checklist!F42="X"))*1) -> 0 | D22: =SUMPRODUCT(((Checklist!G21="X")+(Checklist!G26="X")+(Checklist!G31="X")+(Checklist!G37="X")+(Checklist!G42="X"))*1) -> 0 | E22: =SUMPRODUCT(((Checklist!H21="X")+(Checklist!H26="X")+(Checklist!H31="X")+(Checklist!H37="X")+(Checklist!H42="X"))*1) -> 0 | F22: =IFERROR(C22/5,0) -> 0
A24: Mark X in the Yes / No / In Progress — this dashboard updates automatically | EduDubai: training@edudubai.org
